{
 "cells": [
  {
   "cell_type": "code",
   "execution_count": 1,
   "metadata": {},
   "outputs": [],
   "source": [
    "import boto3, json, sagemaker, io\n",
    "import pandas as pd\n",
    "\n",
    "endpoint = \"huggingface-pytorch-inference-2023-02-17-19-38-32-638\" # fix later\n",
    "\n",
    "runtime = boto3.client(\"sagemaker-runtime\")\n",
    "\n",
    "endpoint_name = endpoint\n"
   ]
  },
  {
   "cell_type": "code",
   "execution_count": 8,
   "metadata": {},
   "outputs": [],
   "source": [
    "df = pd.DataFrame({'A' : [\"this\", \"is\", \"a\", \"test\", \"sentence\"], 'B' : [\"this\", \"is\", \"a\", \"test\", \"sentence\"]})\n",
    "\n",
    "df_1_record = df.T[:1]\n"
   ]
  },
  {
   "cell_type": "code",
   "execution_count": 10,
   "metadata": {},
   "outputs": [],
   "source": [
    "import io\n",
    "from io import StringIO\n",
    "csv_file = io.StringIO()\n",
    "# by default sagemaker expects comma seperated\n",
    "df_1_record.to_csv(csv_file, sep=\",\", header=False, index=False)\n",
    "my_payload_as_csv = csv_file.getvalue()"
   ]
  },
  {
   "cell_type": "code",
   "execution_count": 12,
   "metadata": {},
   "outputs": [
    {
     "data": {
      "text/plain": [
       "'this,is,a,test,sentence\\n'"
      ]
     },
     "execution_count": 12,
     "metadata": {},
     "output_type": "execute_result"
    }
   ],
   "source": [
    "my_payload_as_csv"
   ]
  },
  {
   "cell_type": "code",
   "execution_count": 14,
   "metadata": {},
   "outputs": [
    {
     "ename": "ModelError",
     "evalue": "An error occurred (ModelError) when calling the InvokeEndpoint operation: Received client error (400) from primary with message \"{\n  \"code\": 400,\n  \"type\": \"InternalServerException\",\n  \"message\": \"You need to provide the correct CSV with Header columns to use it with the inference toolkit default handler. : 400\"\n}\n\". See https://us-east-1.console.aws.amazon.com/cloudwatch/home?region=us-east-1#logEventViewer:group=/aws/sagemaker/Endpoints/huggingface-pytorch-inference-2023-02-17-19-38-32-638 in account 663417971547 for more information.",
     "output_type": "error",
     "traceback": [
      "\u001b[0;31m---------------------------------------------------------------------------\u001b[0m",
      "\u001b[0;31mModelError\u001b[0m                                Traceback (most recent call last)",
      "Cell \u001b[0;32mIn[14], line 2\u001b[0m\n\u001b[1;32m      1\u001b[0m client \u001b[39m=\u001b[39m boto3\u001b[39m.\u001b[39mclient(\u001b[39m'\u001b[39m\u001b[39msagemaker-runtime\u001b[39m\u001b[39m'\u001b[39m)\n\u001b[0;32m----> 2\u001b[0m response \u001b[39m=\u001b[39m client\u001b[39m.\u001b[39;49minvoke_endpoint(\n\u001b[1;32m      3\u001b[0m     EndpointName\u001b[39m=\u001b[39;49mendpoint_name,\n\u001b[1;32m      4\u001b[0m     Body\u001b[39m=\u001b[39;49m my_payload_as_csv,\n\u001b[1;32m      5\u001b[0m     ContentType \u001b[39m=\u001b[39;49m \u001b[39m'\u001b[39;49m\u001b[39mtext/csv\u001b[39;49m\u001b[39m'\u001b[39;49m)\n",
      "File \u001b[0;32m~/.python/current/lib/python3.10/site-packages/botocore/client.py:530\u001b[0m, in \u001b[0;36mClientCreator._create_api_method.<locals>._api_call\u001b[0;34m(self, *args, **kwargs)\u001b[0m\n\u001b[1;32m    526\u001b[0m     \u001b[39mraise\u001b[39;00m \u001b[39mTypeError\u001b[39;00m(\n\u001b[1;32m    527\u001b[0m         \u001b[39mf\u001b[39m\u001b[39m\"\u001b[39m\u001b[39m{\u001b[39;00mpy_operation_name\u001b[39m}\u001b[39;00m\u001b[39m() only accepts keyword arguments.\u001b[39m\u001b[39m\"\u001b[39m\n\u001b[1;32m    528\u001b[0m     )\n\u001b[1;32m    529\u001b[0m \u001b[39m# The \"self\" in this scope is referring to the BaseClient.\u001b[39;00m\n\u001b[0;32m--> 530\u001b[0m \u001b[39mreturn\u001b[39;00m \u001b[39mself\u001b[39;49m\u001b[39m.\u001b[39;49m_make_api_call(operation_name, kwargs)\n",
      "File \u001b[0;32m~/.python/current/lib/python3.10/site-packages/botocore/client.py:960\u001b[0m, in \u001b[0;36mBaseClient._make_api_call\u001b[0;34m(self, operation_name, api_params)\u001b[0m\n\u001b[1;32m    958\u001b[0m     error_code \u001b[39m=\u001b[39m parsed_response\u001b[39m.\u001b[39mget(\u001b[39m\"\u001b[39m\u001b[39mError\u001b[39m\u001b[39m\"\u001b[39m, {})\u001b[39m.\u001b[39mget(\u001b[39m\"\u001b[39m\u001b[39mCode\u001b[39m\u001b[39m\"\u001b[39m)\n\u001b[1;32m    959\u001b[0m     error_class \u001b[39m=\u001b[39m \u001b[39mself\u001b[39m\u001b[39m.\u001b[39mexceptions\u001b[39m.\u001b[39mfrom_code(error_code)\n\u001b[0;32m--> 960\u001b[0m     \u001b[39mraise\u001b[39;00m error_class(parsed_response, operation_name)\n\u001b[1;32m    961\u001b[0m \u001b[39melse\u001b[39;00m:\n\u001b[1;32m    962\u001b[0m     \u001b[39mreturn\u001b[39;00m parsed_response\n",
      "\u001b[0;31mModelError\u001b[0m: An error occurred (ModelError) when calling the InvokeEndpoint operation: Received client error (400) from primary with message \"{\n  \"code\": 400,\n  \"type\": \"InternalServerException\",\n  \"message\": \"You need to provide the correct CSV with Header columns to use it with the inference toolkit default handler. : 400\"\n}\n\". See https://us-east-1.console.aws.amazon.com/cloudwatch/home?region=us-east-1#logEventViewer:group=/aws/sagemaker/Endpoints/huggingface-pytorch-inference-2023-02-17-19-38-32-638 in account 663417971547 for more information."
     ]
    }
   ],
   "source": [
    "client = boto3.client('sagemaker-runtime')\n",
    "response = client.invoke_endpoint(\n",
    "    EndpointName=endpoint_name,\n",
    "    Body= my_payload_as_csv,\n",
    "    ContentType = 'text/csv')"
   ]
  },
  {
   "cell_type": "code",
   "execution_count": 17,
   "metadata": {},
   "outputs": [],
   "source": [
    "# write my_payload_as_csv to file\n",
    "with open(\"corpus.csv\", \"w\") as f:\n",
    "    f.write(my_payload_as_csv)"
   ]
  },
  {
   "cell_type": "code",
   "execution_count": 20,
   "metadata": {},
   "outputs": [],
   "source": [
    "payload = io.StringIO()\n",
    "my_payload_as_csv = pd.DataFrame([my_payload_as_csv])\n",
    "my_payload_as_csv.to_csv(payload, header=None, index=None)"
   ]
  },
  {
   "cell_type": "code",
   "execution_count": 27,
   "metadata": {},
   "outputs": [
    {
     "ename": "ModelError",
     "evalue": "An error occurred (ModelError) when calling the InvokeEndpoint operation: Received client error (400) from primary with message \"{\n  \"code\": 400,\n  \"type\": \"InternalServerException\",\n  \"message\": \"You need to provide the correct CSV with Header columns to use it with the inference toolkit default handler. : 400\"\n}\n\". See https://us-east-1.console.aws.amazon.com/cloudwatch/home?region=us-east-1#logEventViewer:group=/aws/sagemaker/Endpoints/huggingface-pytorch-inference-2023-02-17-19-38-32-638 in account 663417971547 for more information.",
     "output_type": "error",
     "traceback": [
      "\u001b[0;31m---------------------------------------------------------------------------\u001b[0m",
      "\u001b[0;31mModelError\u001b[0m                                Traceback (most recent call last)",
      "Cell \u001b[0;32mIn[27], line 4\u001b[0m\n\u001b[1;32m      1\u001b[0m \u001b[39mimport\u001b[39;00m \u001b[39mboto3\u001b[39;00m\n\u001b[1;32m      3\u001b[0m client \u001b[39m=\u001b[39m boto3\u001b[39m.\u001b[39mclient(\u001b[39m'\u001b[39m\u001b[39msagemaker-runtime\u001b[39m\u001b[39m'\u001b[39m)\n\u001b[0;32m----> 4\u001b[0m response \u001b[39m=\u001b[39m client\u001b[39m.\u001b[39;49minvoke_endpoint(\n\u001b[1;32m      5\u001b[0m     EndpointName\u001b[39m=\u001b[39;49mendpoint_name,\n\u001b[1;32m      6\u001b[0m     Body\u001b[39m=\u001b[39;49m \u001b[39mbytes\u001b[39;49m(\u001b[39m\"\u001b[39;49m\u001b[39mThis is great!\u001b[39;49m\u001b[39m\"\u001b[39;49m, \u001b[39m'\u001b[39;49m\u001b[39mutf-8\u001b[39;49m\u001b[39m'\u001b[39;49m),\n\u001b[1;32m      7\u001b[0m     ContentType \u001b[39m=\u001b[39;49m \u001b[39m'\u001b[39;49m\u001b[39mtext/csv\u001b[39;49m\u001b[39m'\u001b[39;49m)\n",
      "File \u001b[0;32m~/.python/current/lib/python3.10/site-packages/botocore/client.py:530\u001b[0m, in \u001b[0;36mClientCreator._create_api_method.<locals>._api_call\u001b[0;34m(self, *args, **kwargs)\u001b[0m\n\u001b[1;32m    526\u001b[0m     \u001b[39mraise\u001b[39;00m \u001b[39mTypeError\u001b[39;00m(\n\u001b[1;32m    527\u001b[0m         \u001b[39mf\u001b[39m\u001b[39m\"\u001b[39m\u001b[39m{\u001b[39;00mpy_operation_name\u001b[39m}\u001b[39;00m\u001b[39m() only accepts keyword arguments.\u001b[39m\u001b[39m\"\u001b[39m\n\u001b[1;32m    528\u001b[0m     )\n\u001b[1;32m    529\u001b[0m \u001b[39m# The \"self\" in this scope is referring to the BaseClient.\u001b[39;00m\n\u001b[0;32m--> 530\u001b[0m \u001b[39mreturn\u001b[39;00m \u001b[39mself\u001b[39;49m\u001b[39m.\u001b[39;49m_make_api_call(operation_name, kwargs)\n",
      "File \u001b[0;32m~/.python/current/lib/python3.10/site-packages/botocore/client.py:960\u001b[0m, in \u001b[0;36mBaseClient._make_api_call\u001b[0;34m(self, operation_name, api_params)\u001b[0m\n\u001b[1;32m    958\u001b[0m     error_code \u001b[39m=\u001b[39m parsed_response\u001b[39m.\u001b[39mget(\u001b[39m\"\u001b[39m\u001b[39mError\u001b[39m\u001b[39m\"\u001b[39m, {})\u001b[39m.\u001b[39mget(\u001b[39m\"\u001b[39m\u001b[39mCode\u001b[39m\u001b[39m\"\u001b[39m)\n\u001b[1;32m    959\u001b[0m     error_class \u001b[39m=\u001b[39m \u001b[39mself\u001b[39m\u001b[39m.\u001b[39mexceptions\u001b[39m.\u001b[39mfrom_code(error_code)\n\u001b[0;32m--> 960\u001b[0m     \u001b[39mraise\u001b[39;00m error_class(parsed_response, operation_name)\n\u001b[1;32m    961\u001b[0m \u001b[39melse\u001b[39;00m:\n\u001b[1;32m    962\u001b[0m     \u001b[39mreturn\u001b[39;00m parsed_response\n",
      "\u001b[0;31mModelError\u001b[0m: An error occurred (ModelError) when calling the InvokeEndpoint operation: Received client error (400) from primary with message \"{\n  \"code\": 400,\n  \"type\": \"InternalServerException\",\n  \"message\": \"You need to provide the correct CSV with Header columns to use it with the inference toolkit default handler. : 400\"\n}\n\". See https://us-east-1.console.aws.amazon.com/cloudwatch/home?region=us-east-1#logEventViewer:group=/aws/sagemaker/Endpoints/huggingface-pytorch-inference-2023-02-17-19-38-32-638 in account 663417971547 for more information."
     ]
    }
   ],
   "source": [
    "import boto3\n",
    "\n",
    "client = boto3.client('sagemaker-runtime')\n",
    "response = client.invoke_endpoint(\n",
    "    EndpointName=endpoint_name,\n",
    "    Body= bytes(\"This is great!\", 'utf-8'),\n",
    "    ContentType = 'text/csv')"
   ]
  },
  {
   "cell_type": "code",
   "execution_count": null,
   "metadata": {},
   "outputs": [],
   "source": []
  }
 ],
 "metadata": {
  "kernelspec": {
   "display_name": "Python 3",
   "language": "python",
   "name": "python3"
  },
  "language_info": {
   "codemirror_mode": {
    "name": "ipython",
    "version": 3
   },
   "file_extension": ".py",
   "mimetype": "text/x-python",
   "name": "python",
   "nbconvert_exporter": "python",
   "pygments_lexer": "ipython3",
   "version": "3.10.4"
  },
  "orig_nbformat": 4,
  "vscode": {
   "interpreter": {
    "hash": "3ad933181bd8a04b432d3370b9dc3b0662ad032c4dfaa4e4f1596c548f763858"
   }
  }
 },
 "nbformat": 4,
 "nbformat_minor": 2
}
